Workbook

Sheet 00_Python_NextSteps
A1: Step | B1: What to do (in Excel) | C1: Why it matters for Python
A2: 1) Fill Inputs | B2: In 01_Inputs: set Scenario, FY start/end, equity ticket, debt rules, fee assumptions, Strict flag. | C2: Defines deterministic baseline; Python will load these cells as scalar inputs.
A3: 2) Paste PIR rows | B3: In 02_PIR_Data_Paste: paste FY24–FY39 rows for each scenario (Net CF, Interest %, NAV Multiple, Mandatory Amort; plus Consortium Fees / FCF of Catalog if Strict=YES). | C3: Python needs the same year-by-year driver series; prevents hidden hardcoding.
A4: 3) Validate mapping | B4: In 03_Map: confirm Scenario selector points to the correct start row for the chosen scenario; recap years list correct. | C4: Avoids off-by-one errors when Python reproduces the mapping logic.
A5: 4) Check engine outputs | B5: In 04_Waterfall: scan that Net CF, Op Fee, Fees, Interest, Debt End, NAV, LTV populate (no blanks/#N/A). | C5: Ensures the Excel “ground truth” is coherent before porting.
A6: 5) Review KPIs | B6: In 05_Outputs: confirm MOIC/IRR and equity cashflow line are populated and plausible. | C6: These become your unit tests for Python.
A7: 6) Run checks | B7: In 06_Checks: ensure all relevant Status cells are OK (or INFO where intended). Fix any FIX flags before exporting. | C7: Prevents importing incomplete scenarios into Python.
A8: 7) Use Export sheet | B8: In 07_Export: use the tidy table (one row per FY) as the single data feed; then Save As → CSV (or read xlsx directly in pandas). | C8: Gives Python a stable schema (columns won’t move even if model layout changes).
A9: 8) Python sanity test | B9: In Python: read 07_Export and replicate 04_Waterfall + 05_Outputs deterministically (no randomness). Compare series & KPIs to Excel. | C9: Locks correctness before you add Monte Carlo / stochastic drivers.
A12: Tip | B12: Keep Excel as the deterministic reference. Only once Python matches 04_Waterfall row-by-row and 05_Outputs KPIs, introduce stochasticity (e.g., Monte Carlo on revenue/Net CF or macro factors).

Sheet 01_Inputs
A1: Input | B1: Value | C1: Notes
A3: Scenario & Horizon
A5: Scenario | B5: Base | C5: Select: Base / CEG / Flat / Downside
A6: Currency | B6: USD | C6: PIR modelling currency
A7: FYE Month/Day | B7: 30.09 | C7: Financial year end (PIR: 30 Sep)
A8: First Projection FY | B8: 2024 | C8: Entry FY
A9: Last Projection FY | B9: 2039 | C9: Exit FY
A11: Debt Facility (PIR-aligned inputs)
A13: Entry Debt (USD m) | B13: 325 | C13: Pre-Securitisation Debt Facility (PIR)
A14: Entry EV (USD m) | B14: 650 | C14: Implied by 50% LTV at entry
A15: Recap Target LTV | B15: 0.6 | C15: Recap years: set Debt to 60% of NAV
A16: Recap Years (comma) | B16: 2026,2029 | C16: If scenario allows refi/recap
A17: Cash Sweep Start FY (Flat/Downside) | B17: 2027 | C17: PIR: from Year 4 onward use 100% FCF for debt amortisation
A19: Covenants (optional, if you want explicit tests)
A21: LTV Covenant | B21: 0.6 | C21: If LTV > covenant => sweep/trap
A22: ICR Trap | B22: 1.35 | C22: ICR < 1.35 => 100% cash trap
A23: ICR Sweep | B23: 1.25 | C23: ICR < 1.25 => 100% cash sweep
A24: ICR Default | B24: 1.1 | C24: ICR < 1.10 => EoD
A26: Fees (catalog/consortium level)
A28: Operating Fee % | B28: 0.05 | C28: PIR: 5% on Net Cashflows to Consortium
A29: Consortium Fees (USD m) | B29: 0.08 | C29: Approx 80k p.a.; keep editable
A31: Strict PIR Mode | B31: YES | C31: YES: require Consortium Fees + FCF of Catalog to be pasted for all FYs. Operating Fee defaults to 5% if blank.
A33: Consortium Equity (USD m) | B33: 99.4 | C33: PIR: PG & Co-investors consortium equity ticket (modelled ~99.4m)
A34: Total Consortium Equity (USD m) | B34: 336.5 | C34: PIR: total consortium equity (for scaling PG & Co-investor share).
A35: PG & Co-investor share of consortium | B35: =IF(B34=0,0,B33/B34) -> 0.29539376 | C35: Used to scale distributions/terminal value to PG & Co-investors.

Sheet 02_PIR_Data_Paste
A1: Base (paste from PIR tables, FY24–FY39)
A2: 2024 | B2: 46.8 | C2: 0.062 | D2: 14 | E2: 0 | G2: 0.2 | H2: 27.6
A3: 2025 | B3: 50.3 | C3: 0.056 | D3: 14 | E3: 0 | G3: 0 | H3: 29.5
A4: 2026 | B4: 53.7 | C4: 0.057 | D4: 14 | E4: 0 | G4: 0 | H4: 28.7
A5: 2027 | B5: 56.3 | C5: 0.057 | D5: 14 | E5: 0 | G5: 0 | H5: 30.3
A6: 2028 | B6: 58.3 | C6: 0.059 | D6: 13.6 | E6: 0 | G6: 0 | H6: 28.9
A7: 2029 | B7: 59.5 | C7: 0.059 | D7: 13.2 | E7: 0 | G7: 0 | H7: 28.3
A8: 2030 | B8: 60.3 | C8: 0.06 | D8: 12.8 | E8: 0 | G8: 0 | H8: 28.8
A9: 2031 | B9: 61.2 | C9: 0.06 | D9: 12.4 | E9: 0 | G9: 0 | H9: 29.4
A10: 2032 | B10: 62.2 | C10: 0.061 | D10: 12 | E10: 0 | G10: 0 | H10: 30.2
A11: 2033 | B11: 63.3 | C11: 0.061 | D11: 12 | E11: 0 | G11: 0 | H11: 30.8
A12: 2034 | B12: 64.3 | C12: 0.062 | D12: 12 | E12: 0 | G12: 0 | H12: 31.5
A13: 2035 | B13: 65.1 | C13: 0.062 | D13: 12 | E13: 0 | G13: 0 | H13: 32.1
... A17: 2039 | B17: 67.5 | C17: 0.062 | D17: 12 | E17: 0 | G17: 0 | H17: 0
A20: CEG (paste from PIR tables, FY24–FY39)
A21: 2024 | B21: 46.4 | C21: 0.062 | D21: 14 | E21: 0 | G21: 0.2 | H21: 28.3
A22: 2025 | B22: 51 | C22: 0.056 | D22: 14 | E22: 0 | G22: 0 | H22: 31.6
A23: 2026 | B23: 56.7 | C23: 0.057 | D23: 14 | E23: 0 | G23: 0 | H23: 30.8
A24: 2027 | B24: 60.2 | C24: 0.057 | D24: 14 | E24: 0 | G24: 0 | H24: 33.2
A25: 2028 | B25: 63.1 | C25: 0.059 | D25: 13.6 | E25: 0 | G25: 0 | H25: 32.2
A26: 2029 | B26: 65.4 | C26: 0.059 | D26: 13.2 | E26: 0 | G26: 0 | H26: 32.4
A27: 2030 | B27: 67.6 | C27: 0.06 | D27: 12.8 | E27: 0 | G27: 0 | H27: 34.5
A28: 2031 | B28: 70.2 | C28: 0.06 | D28: 12.4 | E28: 0 | G28: 0 | H28: 36.9
A29: 2032 | B29: 73.3 | C29: 0.061 | D29: 12 | E29: 0 | G29: 0 | H29: 39.9
A30: 2033 | B30: 76.8 | C30: 0.061 | D30: 12 | E30: 0 | G30: 0 | H30: 43.2
A31: 2034 | B31: 80.5 | C31: 0.062 | D31: 12 | E31: 0 | G31: 0 | H31: 46.8
A32: 2035 | B32: 84.4 | C32: 0.062 | D32: 12 | E32: 0 | G32: 0 | H32: 50.7
... A36: 2039 | B36: 102.9 | C36: 0.062 | D36: 12 | E36: 0 | G36: 0 | H36: 0
A39: Flat (paste from PIR tables, FY24–FY39)
A40: 2024 | B40: 46.1 | C40: 0.062 | D40: 14.1 | E40: 0 | G40: 0.2 | H40: 25.9
A41: 2025 | B41: 48.5 | C41: 0.056 | D41: 13.4 | E41: 0 | G41: 0 | H41: 33.6
A42: 2026 | B42: 54.3 | C42: 0.055 | D42: 12 | E42: 0 | G42: 0 | H42: 35.4
A43: 2027 | B43: 56.1 | C43: 0.061 | D43: 11.6 | E43: 16.5 | G43: 0 | H43: 18
A44: 2028 | B44: 56.8 | C44: 0.067 | D44: 11.4 | E44: 36.7 | G44: 0 | H44: -2.8
A45: 2029 | B45: 56.7 | C45: 0.067 | D45: 11.5 | E45: 38.6 | G45: 0 | H45: -2.8
A46: 2030 | B46: 56.3 | C46: 0.068 | D46: 11.6 | E46: 40.8 | G46: 0 | H46: -2.8
A47: 2031 | B47: 56 | C47: 0.069 | D47: 11.6 | E47: 43.5 | G47: 0 | H47: -2.8
A48: 2032 | B48: 56 | C48: 0.07 | D48: 11.6 | E48: 46.7 | G48: 0 | H48: -2.8
A49: 2033 | B49: 56.2 | C49: 0.068 | D49: 11.6 | E49: 50.5 | G49: 0 | H49: -2.8
A50: 2034 | B50: 56.5 | C50: 0.062 | D50: 11.5 | E50: 51.8 | G50: 0 | H50: 0
...

Sheet 03_Map
A1: Active Scenario | B1: Active Start Row | D1: Scenario | E1: HeaderRow
A2: ='01_Inputs'!B5 -> Base | B2: =INDEX($E$2:$E$5, MATCH(A2, $D$2:$D$5, 0))+1 -> 2 | D2: Base | E2: 1
D3: CEG | E3: 20
A4: Recap Years | B4: ='01_Inputs'!B16 -> 2026,2029 | D4: Flat | E4: 39
A5: Recap Token | B5: =","&SUBSTITUTE(B4," ","")&"," -> ,2026,2029, | D5: Downside | E5: 58
A7: Compatibility | B7: Replaced INDEX with INDEX/MATCH to avoid #NAME? on older Excel.

Sheet 04_Waterfall
A1: FY | B1: Net CF to Consortium | C1: Op Fee | D1: Consortium Fees | E1: CF after Fees | F1: Interest Rate | G1: Interest Cost | H1: Mandatory Amort | I1: Recap ΔDebt | J1: Cash Sweep | K1: Debt End | L1: FCF for Distribution | M1: NAV Multiple | N1: NAV | O1: LTV
A2: 2024 | B2: =INDEX('02_PIR_Data_Paste'!$B:$B,'03_Map'!$B$2+(A2-'01_Inputs'!$B$8)) -> 46.8 | C2: =IF(INDEX('02_PIR_Data_Paste'!$F:$F,'03_Map'!$B$2+(A2-'01_Inputs'!$B$8))<>0,INDEX('02_PIR_Data_Paste'!$F:$F,'03_Map'!$B$2+(A2-'01_Inputs'!$B$8)),'01_Inputs'!$B$28*B2) -> 2.34 | D2: =IF('01_Inputs'!$B$31="YES",INDEX('02_PIR_Data_Paste'!$G:$G,'03_Map'!$B$2+(A2-'01_Inputs'!$B$8)),'01_Inputs'!$B$29) -> 0.2 | E2: =B2-C2-D2 -> 44.26 | F2: =INDEX('02_PIR_Data_Paste'!$C:$C,'03_Map'!$B$2+(A2-'01_Inputs'!$B$8)) -> 0.062 | G2: =-(IF(A2='01_Inputs'!$B$8,'01_Inputs'!$B$13,K1))*F2 -> -20.15 | H2: =INDEX('02_PIR_Data_Paste'!$E:$E,'03_Map'!$B$2+(A2-'01_Inputs'!$B$8)) -> 0 | I2: =IF(AND(OR('03_Map'!$A$2="Base",'03_Map'!$A$2="CEG"),ISNUMBER(SEARCH(","&A2&",",'03_Map'!$B$5))),MAX(0,'01_Inputs'!$B$15*N2-(MAX(0,(IF(A2='01_Inputs'!$B$8,'01_Inputs'!$B$13,K1))-H2)-J2)),0) -> 0 | J2: =IF(OR('03_Map'!$A$2="Flat",'03_Map'!$A$2="Downside"),IF(A2>='01_Inputs'!$B$17,MIN(MAX(0,INDEX('02_PIR_Data_Paste'!$H:$H,'03_Map'!$B$2+(A2-'01_Inputs'!$B$8))),MAX(0,(IF(A2='01_Inputs'!$B$8,'01_Inputs'!$B$13,K1))-H2)),0),0) -> 0 | K2: =MAX(0,MAX(0,(IF(A2='01_Inputs'!$B$8,'01_Inputs'!$B$13,K1))-H2)-J2+I2) -> 325 | L2: =IF($A2='01_Inputs'!$B$9,MAX(0,$N2-$K2),MAX(0,$E2+$G2-$H2-$J2)) -> 24.11 | M2: =INDEX('02_PIR_Data_Paste'!$D:$D,'03_Map'!$B$2+(A2-'01_Inputs'!$B$8)) -> 14 | N2: =M2*B2 -> 655.2 | O2: =IF(N2=0,0,K2/N2) -> 0.49603175
A3: 2025 | B3: =INDEX('02_PIR_Data_Paste'!$B:$B,'03_Map'!$B$2+(A3-'01_Inputs'!$B$8)) -> 50.3 | C3: =IF(INDEX('02_PIR_Data_Paste'!$F:$F,'03_Map'!$B$2+(A3-'01_Inputs'!$B$8))<>0,INDEX('02_PIR_Data_Paste'!$F:$F,'03_Map'!$B$2+(A3-'01_Inputs'!$B$8)),'01_Inputs'!$B$28*B3) -> 2.515 | D3: =IF('01_Inputs'!$B$31="YES",INDEX('02_PIR_Data_Paste'!$G:$G,'03_Map'!$B$2+(A3-'01_Inputs'!$B$8)),'01_Inputs'!$B$29) -> 0 | E3: =B3-C3-D3 -> 47.785 | F3: =INDEX('02_PIR_Data_Paste'!$C:$C,'03_Map'!$B$2+(A3-'01_Inputs'!$B$8)) -> 0.056 | G3: =-(IF(A3='01_Inputs'!$B$8,'01_Inputs'!$B$13,K2))*F3 -> -18.2 | H3: =INDEX('02_PIR_Data_Paste'!$E:$E,'03_Map'!$B$2+(A3-'01_Inputs'!$B$8)) -> 0 | I3: =IF(AND(OR('03_Map'!$A$2="Base",'03_Map'!$A$2="CEG"),ISNUMBER(SEARCH(","&A3&",",'03_Map'!$B$5))),MAX(0,'01_Inputs'!$B$15*N3-(MAX(0,(IF(A3='01_Inputs'!$B$8,'01_Inputs'!$B$13,K2))-H3)-J3)),0) -> 0 | J3: =IF(OR('03_Map'!$A$2="Flat",'03_Map'!$A$2="Downside"),IF(A3>='01_Inputs'!$B$17,MIN(MAX(0,INDEX('02_PIR_Data_Paste'!$H:$H,'03_Map'!$B$2+(A3-'01_Inputs'!$B$8))),MAX(0,(IF(A3='01_Inputs'!$B$8,'01_Inputs'!$B$13,K2))-H3)),0),0) -> 0 | K3: =MAX(0,MAX(0,(IF(A3='01_Inputs'!$B$8,'01_Inputs'!$B$13,K2))-H3)-J3+I3) -> 325 | L3: =IF($A3='01_Inputs'!$B$9,MAX(0,$N3-$K3),MAX(0,$E3+$G3-$H3-$J3)) -> 29.585 | M3: =INDEX('02_PIR_Data_Paste'!$D:$D,'03_Map'!$B$2+(A3-'01_Inputs'!$B$8)) -> 14 | N3: =M3*B3 -> 704.2 | O3: =IF(N3=0,0,K3/N3) -> 0.46151661
A4: 2026 | B4: =INDEX('02_PIR_Data_Paste'!$B:$B,'03_Map'!$B$2+(A4-'01_Inputs'!$B$8)) -> 53.7 | C4: =IF(INDEX('02_PIR_Data_Paste'!$F:$F,'03_Map'!$B$2+(A4-'01_Inputs'!$B$8))<>0,INDEX('02_PIR_Data_Paste'!$F:$F,'03_Map'!$B$2+(A4-'01_Inputs'!$B$8)),'01_Inputs'!$B$28*B4) -> 2.685 | D4: =IF('01_Inputs'!$B$31="YES",INDEX('02_PIR_Data_Paste'!$G:$G,'03_Map'!$B$2+(A4-'01_Inputs'!$B$8)),'01_Inputs'!$B$29) -> 0 | E4: =B4-C4-D4 -> 51.015 | F4: =INDEX('02_PIR_Data_Paste'!$C:$C,'03_Map'!$B$2+(A4-'01_Inputs'!$B$8)) -> 0.057 | G4: =-(IF(A4='01_Inputs'!$B$8,'01_Inputs'!$B$13,K3))*F4 -> -18.525 | H4: =INDEX('02_PIR_Data_Paste'!$E:$E,'03_Map'!$B$2+(A4-'01_Inputs'!$B$8)) -> 0 | I4: =IF(AND(OR('03_Map'!$A$2="Base",'03_Map'!$A$2="CEG"),ISNUMBER(SEARCH(","&A4&",",'03_Map'!$B$5))),MAX(0,'01_Inputs'!$B$15*N4-(MAX(0,(IF(A4='01_Inputs'!$B$8,'01_Inputs'!$B$13,K3))-H4)-J4)),0) -> 126.08 | J4: =IF(OR('03_Map'!$A$2="Flat",'03_Map'!$A$2="Downside"),IF(A4>='01_Inputs'!$B$17,MIN(MAX(0,INDEX('02_PIR_Data_Paste'!$H:$H,'03_Map'!$B$2+(A4-'01_Inputs'!$B$8))),MAX(0,(IF(A4='01_Inputs'!$B$8,'01_Inputs'!$B$13,K3))-H4)),0),0) -> 0 | K4: =MAX(0,MAX(0,(IF(A4='01_Inputs'!$B$8,'01_Inputs'!$B$13,K3))-H4)-J4+I4) -> 451.08 | L4: =IF($A4='01_Inputs'!$B$9,MAX(0,$N4-$K4),MAX(0,$E4+$G4-$H4-$J4)) -> 32.49 | M4: =INDEX('02_PIR_Data_Paste'!$D:$D,'03_Map'!$B$2+(A4-'01_Inputs'!$B$8)) -> 14 | N4: =M4*B4 -> 751.8 | O4: =IF(N4=0,0,K4/N4) -> 0.6
A5: 2027 | B5: =INDEX('02_PIR_Data_Paste'!$B:$B,'03_Map'!$B$2+(A5-'01_Inputs'!$B$8)) -> 56.3 | C5: =IF(INDEX('02_PIR_Data_Paste'!$F:$F,'03_Map'!$B$2+(A5-'01_Inputs'!$B$8))<>0,INDEX('02_PIR_Data_Paste'!$F:$F,'03_Map'!$B$2+(A5-'01_Inputs'!$B$8)),'01_Inputs'!$B$28*B5) -> 2.815 | D5: =IF('01_Inputs'!$B$31="YES",INDEX('02_PIR_Data_Paste'!$G:$G,'03_Map'!$B$2+(A5-'01_Inputs'!$B$8)),'01_Inputs'!$B$29) -> 0 | E5: =B5-C5-D5 -> 53.485 | F5: =INDEX('02_PIR_Data_Paste'!$C:$C,'03_Map'!$B$2+(A5-'01_Inputs'!$B$8)) -> 0.057 | G5: =-(IF(A5='01_Inputs'!$B$8,'01_Inputs'!$B$13,K4))*F5 -> -25.71156 | H5: =INDEX('02_PIR_Data_Paste'!$E:$E,'03_Map'!$B$2+(A5-'01_Inputs'!$B$8)) -> 0 | I5: =IF(AND(OR('03_Map'!$A$2="Base",'03_Map'!$A$2="CEG"),ISNUMBER(SEARCH(","&A5&",",'03_Map'!$B$5))),MAX(0,'01_Inputs'!$B$15*N5-(MAX(0,(IF(A5='01_Inputs'!$B$8,'01_Inputs'!$B$13,K4))-H5)-J5)),0) -> 0 | J5: =IF(OR('03_Map'!$A$2="Flat",'03_Map'!$A$2="Downside"),IF(A5>='01_Inputs'!$B$17,MIN(MAX(0,INDEX('02_PIR_Data_Paste'!$H:$H,'03_Map'!$B$2+(A5-'01_Inputs'!$B$8))),MAX(0,(IF(A5='01_Inputs'!$B$8,'01_Inputs'!$B$13,K4))-H5)),0),0) -> 0 | K5: =MAX(0,MAX(0,(IF(A5='01_Inputs'!$B$8,'01_Inputs'!$B$13,K4))-H5)-J5+I5) -> 451.08 | L5: =IF($A5='01_Inputs'!$B$9,MAX(0,$N5-$K5),MAX(0,$E5+$G5-$H5-$J5)) -> 27.77344 | M5: =INDEX('02_PIR_Data_Paste'!$D:$D,'03_Map'!$B$2+(A5-'01_Inputs'!$B$8)) -> 14 | N5: =M5*B5 -> 788.2 | O5: =IF(N5=0,0,K5/N5) -> 0.5722913
A6: 2028 | B6: =INDEX('02_PIR_Data_Paste'!$B:$B,'03_Map'!$B$2+(A6-'01_Inputs'!$B$8)) -> 58.3 | C6: =IF(INDEX('02_PIR_Data_Paste'!$F:$F,'03_Map'!$B$2+(A6-'01_Inputs'!$B$8))<>0,INDEX('02_PIR_Data_Paste'!$F:$F,'03_Map'!$B$2+(A6-'01_Inputs'!$B$8)),'01_Inputs'!$B$28*B6) -> 2.915 | D6: =IF('01_Inputs'!$B$31="YES",INDEX('02_PIR_Data_Paste'!$G:$G,'03_Map'!$B$2+(A6-'01_Inputs'!$B$8)),'01_Inputs'!$B$29) -> 0 | E6: =B6-C6-D6 -> 55.385 | F6: =INDEX('02_PIR_Data_Paste'!$C:$C,'03_Map'!$B$2+(A6-'01_Inputs'!$B$8)) -> 0.059 | G6: =-(IF(A6='01_Inputs'!$B$8,'01_Inputs'!$B$13,K5))*F6 -> -26.61372 | H6: =INDEX('02_PIR_Data_Paste'!$E:$E,'03_Map'!$B$2+(A6-'01_Inputs'!$B$8)) -> 0 | I6: =IF(AND(OR('03_Map'!$A$2="Base",'03_Map'!$A$2="CEG"),ISNUMBER(SEARCH(","&A6&",",'03_Map'!$B$5))),MAX(0,'01_Inputs'!$B$15*N6-(MAX(0,(IF(A6='01_Inputs'!$B$8,'01_Inputs'!$B$13,K5))-H6)-J6)),0) -> 0 | J6: =IF(OR('03_Map'!$A$2="Flat",'03_Map'!$A$2="Downside"),IF(A6>='01_Inputs'!$B$17,MIN(MAX(0,INDEX('02_PIR_Data_Paste'!$H:$H,'03_Map'!$B$2+(A6-'01_Inputs'!$B$8))),MAX(0,(IF(A6='01_Inputs'!$B$8,'01_Inputs'!$B$13,K5))-H6)),0),0) -> 0 | K6: =MAX(0,MAX(0,(IF(A6='01_Inputs'!$B$8,'01_Inputs'!$B$13,K5))-H6)-J6+I6) -> 451.08 | L6: =IF($A6='01_Inputs'!$B$9,MAX(0,$N6-$K6),MAX(0,$E6+$G6-$H6-$J6)) -> 28.77128 | M6: =INDEX('02_PIR_Data_Paste'!$D:$D,'03_Map'!$B$2+(A6-'01_Inputs'!$B$8)) -> 13.6 | N6: =M6*B6 -> 792.88 | O6: =IF(N6=0,0,K6/N6) -> 0.56891333
A7: 2029 | B7: =INDEX('02_PIR_Data_Paste'!$B:$B,'03_Map'!$B$2+(A7-'01_Inputs'!$B$8)) -> 59.5 | C7: =IF(INDEX('02_PIR_Data_Paste'!$F:$F,'03_Map'!$B$2+(A7-'01_Inputs'!$B$8))<>0,INDEX('02_PIR_Data_Paste'!$F:$F,'03_Map'!$B$2+(A7-'01_Inputs'!$B$8)),'01_Inputs'!$B$28*B7) -> 2.975 | D7: =IF('01_Inputs'!$B$31="YES",INDEX('02_PIR_Data_Paste'!$G:$G,'03_Map'!$B$2+(A7-'01_Inputs'!$B$8)),'01_Inputs'!$B$29) -> 0 | E7: =B7-C7-D7 -> 56.525 | F7: =INDEX('02_PIR_Data_Paste'!$C:$C,'03_Map'!$B$2+(A7-'01_Inputs'!$B$8)) -> 0.059 | G7: =-(IF(A7='01_Inputs'!$B$8,'01_Inputs'!$B$13,K6))*F7 -> -26.61372 | H7: =INDEX('02_PIR_Data_Paste'!$E:$E,'03_Map'!$B$2+(A7-'01_Inputs'!$B$8)) -> 0 | I7: =IF(AND(OR('03_Map'!$A$2="Base",'03_Map'!$A$2="CEG"),ISNUMBER(SEARCH(","&A7&",",'03_Map'!$B$5))),MAX(0,'01_Inputs'!$B$15*N7-(MAX(0,(IF(A7='01_Inputs'!$B$8,'01_Inputs'!$B$13,K6))-H7)-J7)),0) -> 20.16 | J7: =IF(OR('03_Map'!$A$2="Flat",'03_Map'!$A$2="Downside"),IF(A7>='01_Inputs'!$B$17,MIN(MAX(0,INDEX('02_PIR_Data_Paste'!$H:$H,'03_Map'!$B$2+(A7-'01_Inputs'!$B$8))),MAX(0,(IF(A7='01_Inputs'!$B$8,'01_Inputs'!$B$13,K6))-H7)),0),0) -> 0 | K7: =MAX(0,MAX(0,(IF(A7='01_Inputs'!$B$8,'01_Inputs'!$B$13,K6))-H7)-J7+I7) -> 471.24 | L7: =IF($A7='01_Inputs'!$B$9,MAX(0,$N7-$K7),MAX(0,$E7+$G7-$H7-$J7)) -> 29.91128 | M7: =INDEX('02_PIR_Data_Paste'!$D:$D,'03_Map'!$B$2+(A7-'01_Inputs'!$B$8)) -> 13.2 | N7: =M7*B7 -> 785.4 | O7: =IF(N7=0,0,K7/N7) -> 0.6
A8: 2030 | B8: =INDEX('02_PIR_Data_Paste'!$B:$B,'03_Map'!$B$2+(A8-'01_Inputs'!$B$8)) -> 60.3 | C8: =IF(INDEX('02_PIR_Data_Paste'!$F:$F,'03_Map'!$B$2+(A8-'01_Inputs'!$B$8))<>0,INDEX('02_PIR_Data_Paste'!$F:$F,'03_Map'!$B$2+(A8-'01_Inputs'!$B$8)),'01_Inputs'!$B$28*B8) -> 3.015 | D8: =IF('01_Inputs'!$B$31="YES",INDEX('02_PIR_Data_Paste'!$G:$G,'03_Map'!$B$2+(A8-'01_Inputs'!$B$8)),'01_Inputs'!$B$29) -> 0 | E8: =B8-C8-D8 -> 57.285 | F8: =INDEX('02_PIR_Data_Paste'!$C:$C,'03_Map'!$B$2+(A8-'01_Inputs'!$B$8)) -> 0.06 | G8: =-(IF(A8='01_Inputs'!$B$8,'01_Inputs'!$B$13,K7))*F8 -> -28.2744 | H8: =INDEX('02_PIR_Data_Paste'!$E:$E,'03_Map'!$B$2+(A8-'01_Inputs'!$B$8)) -> 0 | I8: =IF(AND(OR('03_Map'!$A$2="Base",'03_Map'!$A$2="CEG"),ISNUMBER(SEARCH(","&A8&",",'03_Map'!$B$5))),MAX(0,'01_Inputs'!$B$15*N8-(MAX(0,(IF(A8='01_Inputs'!$B$8,'01_Inputs'!$B$13,K7))-H8)-J8)),0) -> 0 | J8: =IF(OR('03_Map'!$A$2="Flat",'03_Map'!$A$2="Downside"),IF(A8>='01_Inputs'!$B$17,MIN(MAX(0,INDEX('02_PIR_Data_Paste'!$H:$H,'03_Map'!$B$2+(A8-'01_Inputs'!$B$8))),MAX(0,(IF(A8='01_Inputs'!$B$8,'01_Inputs'!$B$13,K7))-H8)),0),0) -> 0 | K8: =MAX(0,MAX(0,(IF(A8='01_Inputs'!$B$8,'01_Inputs'!$B$13,K7))-H8)-J8+I8) -> 471.24 | L8: =IF($A8='01_Inputs'!$B$9,MAX(0,$N8-$K8),MAX(0,$E8+$G8-$H8-$J8)) -> 29.0106 | M8: =INDEX('02_PIR_Data_Paste'!$D:$D,'03_Map'!$B$2+(A8-'01_Inputs'!$B$8)) -> 12.8 | N8: =M8*B8 -> 771.84 | O8: =IF(N8=0,0,K8/N8) -> 0.61054104
A9: 2031 | B9: =INDEX('02_PIR_Data_Paste'!$B:$B,'03_Map'!$B$2+(A9-'01_Inputs'!$B$8)) -> 61.2 | C9: =IF(INDEX('02_PIR_Data_Paste'!$F:$F,'03_Map'!$B$2+(A9-'01_Inputs'!$B$8))<>0,INDEX('02_PIR_Data_Paste'!$F:$F,'03_Map'!$B$2+(A9-'01_Inputs'!$B$8)),'01_Inputs'!$B$28*B9) -> 3.06 | D9: =IF('01_Inputs'!$B$31="YES",INDEX('02_PIR_Data_Paste'!$G:$G,'03_Map'!$B$2+(A9-'01_Inputs'!$B$8)),'01_Inputs'!$B$29) -> 0 | E9: =B9-C9-D9 -> 58.14 | F9: =INDEX('02_PIR_Data_Paste'!$C:$C,'03_Map'!$B$2+(A9-'01_Inputs'!$B$8)) -> 0.06 | G9: =-(IF(A9='01_Inputs'!$B$8,'01_Inputs'!$B$13,K8))*F9 -> -28.2744 | H9: =INDEX('02_PIR_Data_Paste'!$E:$E,'03_Map'!$B$2+(A9-'01_Inputs'!$B$8)) -> 0 | I9: =IF(AND(OR('03_Map'!$A$2="Base",'03_Map'!$A$2="CEG"),ISNUMBER(SEARCH(","&A9&",",'03_Map'!$B$5))),MAX(0,'01_Inputs'!$B$15*N9-(MAX(0,(IF(A9='01_Inputs'!$B$8,'01_Inputs'!$B$13,K8))-H9)-J9)),0) -> 0 | J9: =IF(OR('03_Map'!$A$2="Flat",'03_Map'!$A$2="Downside"),IF(A9>='01_Inputs'!$B$17,MIN(MAX(0,INDEX('02_PIR_Data_Paste'!$H:$H,'03_Map'!$B$2+(A9-'01_Inputs'!$B$8))),MAX(0,(IF(A9='01_Inputs'!$B$8,'01_Inputs'!$B$13,K8))-H9)),0),0) -> 0 | K9: =MAX(0,MAX(0,(IF(A9='01_Inputs'!$B$8,'01_Inputs'!$B$13,K8))-H9)-J9+I9) -> 471.24 | L9: =IF($A9='01_Inputs'!$B$9,MAX(0,$N9-$K9),MAX(0,$E9+$G9-$H9-$J9)) -> 29.8656 | M9: =INDEX('02_PIR_Data_Paste'!$D:$D,'03_Map'!$B$2+(A9-'01_Inputs'!$B$8)) -> 12.4 | N9: =M9*B9 -> 758.88 | O9: =IF(N9=0,0,K9/N9) -> 0.62096774
A10: 2032 | B10: =INDEX('02_PIR_Data_Paste'!$B:$B,'03_Map'!$B$2+(A10-'01_Inputs'!$B$8)) -> 62.2 | C10: =IF(INDEX('02_PIR_Data_Paste'!$F:$F,'03_Map'!$B$2+(A10-'01_Inputs'!$B$8))<>0,INDEX('02_PIR_Data_Paste'!$F:$F,'03_Map'!$B$2+(A10-'01_Inputs'!$B$8)),'01_Inputs'!$B$28*B10) -> 3.11 | D10: =IF('01_Inputs'!$B$31="YES",INDEX('02_PIR_Data_Paste'!$G:$G,'03_Map'!$B$2+(A10-'01_Inputs'!$B$8)),'01_Inputs'!$B$29) -> 0 | E10: =B10-C10-D10 -> 59.09 | F10: =INDEX('02_PIR_Data_Paste'!$C:$C,'03_Map'!$B$2+(A10-'01_Inputs'!$B$8)) -> 0.061 | G10: =-(IF(A10='01_Inputs'!$B$8,'01_Inputs'!$B$13,K9))*F10 -> -28.74564 | H10: =INDEX('02_PIR_Data_Paste'!$E:$E,'03_Map'!$B$2+(A10-'01_Inputs'!$B$8)) -> 0 | I10: =IF(AND(OR('03_Map'!$A$2="Base",'03_Map'!$A$2="CEG"),ISNUMBER(SEARCH(","&A10&",",'03_Map'!$B$5))),MAX(0,'01_Inputs'!$B$15*N10-(MAX(0,(IF(A10='01_Inputs'!$B$8,'01_Inputs'!$B$13,K9))-H10)-J10)),0) -> 0 | J10: =IF(OR('03_Map'!$A$2="Flat",'03_Map'!$A$2="Downside"),IF(A10>='01_Inputs'!$B$17,MIN(MAX(0,INDEX('02_PIR_Data_Paste'!$H:$H,'03_Map'!$B$2+(A10-'01_Inputs'!$B$8))),MAX(0,(IF(A10='01_Inputs'!$B$8,'01_Inputs'!$B$13,K9))-H10)),0),0) -> 0 | K10: =MAX(0,MAX(0,(IF(A10='01_Inputs'!$B$8,'01_Inputs'!$B$13,K9))-H10)-J10+I10) -> 471.24 | L10: =IF($A10='01_Inputs'!$B$9,MAX(0,$N10-$K10),MAX(0,$E10+$G10-$H10-$J10)) -> 30.34436 | M10: =INDEX('02_PIR_Data_Paste'!$D:$D,'03_Map'!$B$2+(A10-'01_Inputs'!$B$8)) -> 12 | N10: =M10*B10 -> 746.4 | O10: =IF(N10=0,0,K10/N10) -> 0.63135048
A11: 2033 | B11: =INDEX('02_PIR_Data_Paste'!$B:$B,'03_Map'!$B$2+(A11-'01_Inputs'!$B$8)) -> 63.3 | C11: =IF(INDEX('02_PIR_Data_Paste'!$F:$F,'03_Map'!$B$2+(A11-'01_Inputs'!$B$8))<>0,INDEX('02_PIR_Data_Paste'!$F:$F,'03_Map'!$B$2+(A11-'01_Inputs'!$B$8)),'01_Inputs'!$B$28*B11) -> 3.165 | D11: =IF('01_Inputs'!$B$31="YES",INDEX('02_PIR_Data_Paste'!$G:$G,'03_Map'!$B$2+(A11-'01_Inputs'!$B$8)),'01_Inputs'!$B$29) -> 0 | E11: =B11-C11-D11 -> 60.135 | F11: =INDEX('02_PIR_Data_Paste'!$C:$C,'03_Map'!$B$2+(A11-'01_Inputs'!$B$8)) -> 0.061 | G11: =-(IF(A11='01_Inputs'!$B$8,'01_Inputs'!$B$13,K10))*F11 -> -28.74564 | H11: =INDEX('02_PIR_Data_Paste'!$E:$E,'03_Map'!$B$2+(A11-'01_Inputs'!$B$8)) -> 0 | I11: =IF(AND(OR('03_Map'!$A$2="Base",'03_Map'!$A$2="CEG"),ISNUMBER(SEARCH(","&A11&",",'03_Map'!$B$5))),MAX(0,'01_Inputs'!$B$15*N11-(MAX(0,(IF(A11='01_Inputs'!$B$8,'01_Inputs'!$B$13,K10))-H11)-J11)),0) -> 0 | J11: =IF(OR('03_Map'!$A$2="Flat",'03_Map'!$A$2="Downside"),IF(A11>='01_Inputs'!$B$17,MIN(MAX(0,INDEX('02_PIR_Data_Paste'!$H:$H,'03_Map'!$B$2+(A11-'01_Inputs'!$B$8))),MAX(0,(IF(A11='01_Inputs'!$B$8,'01_Inputs'!$B$13,K10))-H11)),0),0) -> 0 | K11: =MAX(0,MAX(0,(IF(A11='01_Inputs'!$B$8,'01_Inputs'!$B$13,K10))-H11)-J11+I11) -> 471.24 | L11: =IF($A11='01_Inputs'!$B$9,MAX(0,$N11-$K11),MAX(0,$E11+$G11-$H11-$J11)) -> 31.38936 | M11: =INDEX('02_PIR_Data_Paste'!$D:$D,'03_Map'!$B$2+(A11-'01_Inputs'!$B$8)) -> 12 | N11: =M11*B11 -> 759.6 | O11: =IF(N11=0,0,K11/N11) -> 0.62037915
A12: 2034 | B12: =INDEX('02_PIR_Data_Paste'!$B:$B,'03_Map'!$B$2+(A12-'01_Inputs'!$B$8)) -> 64.3 | C12: =IF(INDEX('02_PIR_Data_Paste'!$F:$F,'03_Map'!$B$2+(A12-'01_Inputs'!$B$8))<>0,INDEX('02_PIR_Data_Paste'!$F:$F,'03_Map'!$B$2+(A12-'01_Inputs'!$B$8)),'01_Inputs'!$B$28*B12) -> 3.215 | D12: =IF('01_Inputs'!$B$31="YES",INDEX('02_PIR_Data_Paste'!$G:$G,'03_Map'!$B$2+(A12-'01_Inputs'!$B$8)),'01_Inputs'!$B$29) -> 0 | E12: =B12-C12-D12 -> 61.085 | F12: =INDEX('02_PIR_Data_Paste'!$C:$C,'03_Map'!$B$2+(A12-'01_Inputs'!$B$8)) -> 0.062 | G12: =-(IF(A12='01_Inputs'!$B$8,'01_Inputs'!$B$13,K11))*F12 -> -29.21688 | H12: =INDEX('02_PIR_Data_Paste'!$E:$E,'03_Map'!$B$2+(A12-'01_Inputs'!$B$8)) -> 0 | I12: =IF(AND(OR('03_Map'!$A$2="Base",'03_Map'!$A$2="CEG"),ISNUMBER(SEARCH(","&A12&",",'03_Map'!$B$5))),MAX(0,'01_Inputs'!$B$15*N12-(MAX(0,(IF(A12='01_Inputs'!$B$8,'01_Inputs'!$B$13,K11))-H12)-J12)),0) -> 0 | J12: =IF(OR('03_Map'!$A$2="Flat",'03_Map'!$A$2="Downside"),IF(A12>='01_Inputs'!$B$17,MIN(MAX(0,INDEX('02_PIR_Data_Paste'!$H:$H,'03_Map'!$B$2+(A12-'01_Inputs'!$B$8))),MAX(0,(IF(A12='01_Inputs'!$B$8,'01_Inputs'!$B$13,K11))-H12)),0),0) -> 0 | K12: =MAX(0,MAX(0,(IF(A12='01_Inputs'!$B$8,'01_Inputs'!$B$13,K11))-H12)-J12+I12) -> 471.24 | L12: =IF($A12='01_Inputs'!$B$9,MAX(0,$N12-$K12),MAX(0,$E12+$G12-$H12-$J12)) -> 31.86812 | M12: =INDEX('02_PIR_Data_Paste'!$D:$D,'03_Map'!$B$2+(A12-'01_Inputs'!$B$8)) -> 12 | N12: =M12*B12 -> 771.6 | O12: =IF(N12=0,0,K12/N12) -> 0.61073095
A13: 2035 | B13: =INDEX('02_PIR_Data_Paste'!$B:$B,'03_Map'!$B$2+(A13-'01_Inputs'!$B$8)) -> 65.1 | C13: =IF(INDEX('02_PIR_Data_Paste'!$F:$F,'03_Map'!$B$2+(A13-'01_Inputs'!$B$8))<>0,INDEX('02_PIR_Data_Paste'!$F:$F,'03_Map'!$B$2+(A13-'01_Inputs'!$B$8)),'01_Inputs'!$B$28*B13) -> 3.255 | D13: =IF('01_Inputs'!$B$31="YES",INDEX('02_PIR_Data_Paste'!$G:$G,'03_Map'!$B$2+(A13-'01_Inputs'!$B$8)),'01_Inputs'!$B$29) -> 0 | E13: =B13-C13-D13 -> 61.845 | F13: =INDEX('02_PIR_Data_Paste'!$C:$C,'03_Map'!$B$2+(A13-'01_Inputs'!$B$8)) -> 0.062 | G13: =-(IF(A13='01_Inputs'!$B$8,'01_Inputs'!$B$13,K12))*F13 -> -29.21688 | H13: =INDEX('02_PIR_Data_Paste'!$E:$E,'03_Map'!$B$2+(A13-'01_Inputs'!$B$8)) -> 0 | I13: =IF(AND(OR('03_Map'!$A$2="Base",'03_Map'!$A$2="CEG"),ISNUMBER(SEARCH(","&A13&",",'03_Map'!$B$5))),MAX(0,'01_Inputs'!$B$15*N13-(MAX(0,(IF(A13='01_Inputs'!$B$8,'01_Inputs'!$B$13,K12))-H13)-J13)),0) -> 0 | J13: =IF(OR('03_Map'!$A$2="Flat",'03_Map'!$A$2="Downside"),IF(A13>='01_Inputs'!$B$17,MIN(MAX(0,INDEX('02_PIR_Data_Paste'!$H:$H,'03_Map'!$B$2+(A13-'01_Inputs'!$B$8))),MAX(0,(IF(A13='01_Inputs'!$B$8,'01_Inputs'!$B$13,K12))-H13)),0),0) -> 0 | K13: =MAX(0,MAX(0,(IF(A13='01_Inputs'!$B$8,'01_Inputs'!$B$13,K12))-H13)-J13+I13) -> 471.24 | L13: =IF($A13='01_Inputs'!$B$9,MAX(0,$N13-$K13),MAX(0,$E13+$G13-$H13-$J13)) -> 32.62812 | M13: =INDEX('02_PIR_Data_Paste'!$D:$D,'03_Map'!$B$2+(A13-'01_Inputs'!$B$8)) -> 12 | N13: =M13*B13 -> 781.2 | O13: =IF(N13=0,0,K13/N13) -> 0.60322581
... A17: 2039 | B17: =INDEX('02_PIR_Data_Paste'!$B:$B,'03_Map'!$B$2+(A17-'01_Inputs'!$B$8)) -> 67.5 | C17: =IF(INDEX('02_PIR_Data_Paste'!$F:$F,'03_Map'!$B$2+(A17-'01_Inputs'!$B$8))<>0,INDEX('02_PIR_Data_Paste'!$F:$F,'03_Map'!$B$2+(A17-'01_Inputs'!$B$8)),'01_Inputs'!$B$28*B17) -> 3.375 | D17: =IF('01_Inputs'!$B$31="YES",INDEX('02_PIR_Data_Paste'!$G:$G,'03_Map'!$B$2+(A17-'01_Inputs'!$B$8)),'01_Inputs'!$B$29) -> 0 | E17: =B17-C17-D17 -> 64.125 | F17: =INDEX('02_PIR_Data_Paste'!$C:$C,'03_Map'!$B$2+(A17-'01_Inputs'!$B$8)) -> 0.062 | G17: =-(IF(A17='01_Inputs'!$B$8,'01_Inputs'!$B$13,K16))*F17 -> -29.21688 | H17: =INDEX('02_PIR_Data_Paste'!$E:$E,'03_Map'!$B$2+(A17-'01_Inputs'!$B$8)) -> 0 | I17: =IF(AND(OR('03_Map'!$A$2="Base",'03_Map'!$A$2="CEG"),ISNUMBER(SEARCH(","&A17&",",'03_Map'!$B$5))),MAX(0,'01_Inputs'!$B$15*N17-(MAX(0,(IF(A17='01_Inputs'!$B$8,'01_Inputs'!$B$13,K16))-H17)-J17)),0) -> 0 | J17: =IF(OR('03_Map'!$A$2="Flat",'03_Map'!$A$2="Downside"),IF(A17>='01_Inputs'!$B$17,MIN(MAX(0,INDEX('02_PIR_Data_Paste'!$H:$H,'03_Map'!$B$2+(A17-'01_Inputs'!$B$8))),MAX(0,(IF(A17='01_Inputs'!$B$8,'01_Inputs'!$B$13,K16))-H17)),0),0) -> 0 | K17: =MAX(0,MAX(0,(IF(A17='01_Inputs'!$B$8,'01_Inputs'!$B$13,K16))-H17)-J17+I17) -> 471.24 | L17: =IF($A17='01_Inputs'!$B$9,MAX(0,$N17-$K17),MAX(0,$E17+$G17-$H17-$J17)) -> 338.76 | M17: =INDEX('02_PIR_Data_Paste'!$D:$D,'03_Map'!$B$2+(A17-'01_Inputs'!$B$8)) -> 12 | N17: =M17*B17 -> 810 | O17: =IF(N17=0,0,K17/N17) -> 0.58177778

Sheet 05_Outputs
A1: Metric | B1: Value | C1: Notes
A2: Scenario | B2: ='01_Inputs'!B5 -> Base
A3: Total Distributions (USD m) | B3: ='01_Inputs'!$B$35*SUM('04_Waterfall'!$L$2:$L$17) -> 235.75273 | C3: PG & Co-investor share * consortium distributions (incl. terminal).
A4: Max Debt (USD m) | B4: =MAX('04_Waterfall'!K2:K17) -> 471.24
A5: Min LTV | B5: =MIN('04_Waterfall'!O2:O17) -> 0.46151661
A6: Max LTV | B6: =MAX('04_Waterfall'!O2:O17) -> 0.63135048
A7: Exit NAV (FY39) | B7: ='04_Waterfall'!N17 -> 810
A8: Exit Debt (FY39) | B8: ='04_Waterfall'!K17 -> 471.24
A9: Net Equity Value at Exit | B9: ='01_Inputs'!$B$35*('04_Waterfall'!N17-'04_Waterfall'!K17) -> 100.06759 | C9: Scaled by PG & Co-investor share.
A10: Notes | C10: Paste PIR year-by-year rows into 02_PIR_Data_Paste for each scenario. This template does not invent any numbers.
A11: Equity Ticket (USD m) | B11: ='01_Inputs'!B33 -> 99.4
A12: MOIC (Distributions / Equity) | B12: =IF(B11=0,0,B3/B11) -> 2.3717579
A13: IRR (annual) | B13: =IFERROR(IRR($B$16:$B$31),"") -> 0.097465119
A15: FY | B15: Equity CF (USD m)
A16: 2024 | B16: =-B11+'01_Inputs'!$B$35*'04_Waterfall'!L2 -> -92.278056
A17: 2025 | B17: ='01_Inputs'!$B$35*'04_Waterfall'!L3 -> 8.7392244
A18: 2026 | B18: ='01_Inputs'!$B$35*'04_Waterfall'!L4 -> 9.5973432
A19: 2027 | B19: ='01_Inputs'!$B$35*'04_Waterfall'!L5 -> 8.2041008
A20: 2028 | B20: ='01_Inputs'!$B$35*'04_Waterfall'!L6 -> 8.4988566
A21: 2029 | B21: ='01_Inputs'!$B$35*'04_Waterfall'!L7 -> 8.8356054
A22: 2030 | B22: ='01_Inputs'!$B$35*'04_Waterfall'!L8 -> 8.5695502
A23: 2031 | B23: ='01_Inputs'!$B$35*'04_Waterfall'!L9 -> 8.8221119
A24: 2032 | B24: ='01_Inputs'!$B$35*'04_Waterfall'!L10 -> 8.9635346
A25: 2033 | B25: ='01_Inputs'!$B$35*'04_Waterfall'!L11 -> 9.2722211
A26: 2034 | B26: ='01_Inputs'!$B$35*'04_Waterfall'!L12 -> 9.4136438
A27: 2035 | B27: ='01_Inputs'!$B$35*'04_Waterfall'!L13 -> 9.638143
A28: 2036 | B28: ='01_Inputs'!$B$35*'04_Waterfall'!L14 -> 9.8345799
... A31: 2039 | B31: ='01_Inputs'!$B$35*'04_Waterfall'!L17 -> 100.06759

Sheet 06_Checks
A1: Check | B1: Result | C1: Status | D1: Action
A2: Consortium Fees pasted (all FYs, active scenario) | B2: =IF('01_Inputs'!$B$31="YES",COUNTBLANK('04_Waterfall'!$D$2:$D$17)+COUNTIF('04_Waterfall'!$D$2:$D$17,"#N/A"),0) -> 0 | C2: =IF($B2=0,"OK","FIX") -> OK | D2: If Strict=YES, paste PIR 'Consortium Fees' row (USD m) for FY24–FY39.
A3: FCF of Catalog pasted (Flat/Downside sweep relies on it) | B3: =COUNTIF('04_Waterfall'!J2:J17,"#N/A") -> 0 | C3: =IF('01_Inputs'!B31="YES",IF(B3=0,"OK","FIX"),"INFO") -> OK | D3: If Strict=YES, paste PIR 'Free Cash Flow of Catalog' row (USD m).
A4: Operating Fee override usage (optional) | B4: =COUNTIF('02_PIR_Data_Paste'!F:F,">0") -> 0 | C4: INFO | D4: You may paste Operating Fee row; otherwise model uses 5% of Net CF to Consortium.
A6: Export table complete (no blanks) | B6: =COUNTBLANK('07_Export'!A2:S17) -> 0 | C6: =IF(B6=0,"OK","FIX") -> OK | D6: If FIX: ensure 07_Export has 16 FY rows (2024–2039) and no blanks/hidden #N/A.
A7: Export table error-free (#N/A/#REF/etc.) | B7: =COUNTIF('07_Export'!A2:S17,"#N/A")+COUNTIF('07_Export'!A2:S17,"#REF!")+COUNTIF('07_Export'!A2:S17,"#DIV/0!")+COUNTIF('07_Export'!A2:S17,"#VALUE!")+COUNTIF('07_Export'!A2:S17,"#NAME?") -> 0 | C7: =IF(B7=0,"OK","FIX") -> OK | D7: If FIX: trace upstream formulas in 04_Waterfall / 05_Outputs.

Sheet 07_Export
A1: Scenario | B1: FY | C1: Net_CF_to_Consortium | D1: Op_Fee | E1: Consortium_Fees | F1: CF_after_Fees | G1: Interest_Rate | H1: Interest_Cost | I1: Mandatory_Amort | J1: Recap_DeltaDebt | K1: Cash_Sweep | L1: Debt_End | M1: FCF_for_Distribution | N1: NAV_Multiple | O1: NAV | P1: LTV | Q1: PG_Share | R1: Equity_Ticket | S1: Equity_CF
A2: ='01_Inputs'!$B$5 -> Base | B2: ='04_Waterfall'!A2 -> 2024 | C2: ='04_Waterfall'!B2 -> 46.8 | D2: ='04_Waterfall'!C2 -> 2.34 | E2: ='04_Waterfall'!D2 -> 0.2 | F2: ='04_Waterfall'!E2 -> 44.26 | G2: ='04_Waterfall'!F2 -> 0.062 | H2: ='04_Waterfall'!G2 -> -20.15 | I2: ='04_Waterfall'!H2 -> 0 | ... P2: ='04_Waterfall'!O2 -> 0.49603175 | Q2: ='01_Inputs'!$B$35 -> 0.29539376 | R2: ='01_Inputs'!$B$33 -> 99.4 | S2: ='05_Outputs'!B16 -> -92.278056
A3: ='01_Inputs'!$B$5 -> Base | B3: ='04_Waterfall'!A3 -> 2025 | C3: ='04_Waterfall'!B3 -> 50.3 | D3: ='04_Waterfall'!C3 -> 2.515 | E3: ='04_Waterfall'!D3 -> 0 | F3: ='04_Waterfall'!E3 -> 47.785 | G3: ='04_Waterfall'!F3 -> 0.056 | H3: ='04_Waterfall'!G3 -> -18.2 | I3: ='04_Waterfall'!H3 -> 0 | ... P3: ='04_Waterfall'!O3 -> 0.46151661 | Q3: ='01_Inputs'!$B$35 -> 0.29539376 | R3: ='01_Inputs'!$B$33 -> 99.4 | S3: ='05_Outputs'!B17 -> 8.7392244
A4: ='01_Inputs'!$B$5 -> Base | B4: ='04_Waterfall'!A4 -> 2026 | C4: ='04_Waterfall'!B4 -> 53.7 | D4: ='04_Waterfall'!C4 -> 2.685 | E4: ='04_Waterfall'!D4 -> 0 | F4: ='04_Waterfall'!E4 -> 51.015 | G4: ='04_Waterfall'!F4 -> 0.057 | H4: ='04_Waterfall'!G4 -> -18.525 | I4: ='04_Waterfall'!H4 -> 0 | ... P4: ='04_Waterfall'!O4 -> 0.6 | Q4: ='01_Inputs'!$B$35 -> 0.29539376 | R4: ='01_Inputs'!$B$33 -> 99.4 | S4: ='05_Outputs'!B18 -> 9.5973432
A5: ='01_Inputs'!$B$5 -> Base | B5: ='04_Waterfall'!A5 -> 2027 | C5: ='04_Waterfall'!B5 -> 56.3 | D5: ='04_Waterfall'!C5 -> 2.815 | E5: ='04_Waterfall'!D5 -> 0 | F5: ='04_Waterfall'!E5 -> 53.485 | G5: ='04_Waterfall'!F5 -> 0.057 | H5: ='04_Waterfall'!G5 -> -25.71156 | I5: ='04_Waterfall'!H5 -> 0 | ... P5: ='04_Waterfall'!O5 -> 0.5722913 | Q5: ='01_Inputs'!$B$35 -> 0.29539376 | R5: ='01_Inputs'!$B$33 -> 99.4 | S5: ='05_Outputs'!B19 -> 8.2041008
A6: ='01_Inputs'!$B$5 -> Base | B6: ='04_Waterfall'!A6 -> 2028 | C6: ='04_Waterfall'!B6 -> 58.3 | D6: ='04_Waterfall'!C6 -> 2.915 | E6: ='04_Waterfall'!D6 -> 0 | F6: ='04_Waterfall'!E6 -> 55.385 | G6: ='04_Waterfall'!F6 -> 0.059 | H6: ='04_Waterfall'!G6 -> -26.61372 | I6: ='04_Waterfall'!H6 -> 0 | ... P6: ='04_Waterfall'!O6 -> 0.56891333 | Q6: ='01_Inputs'!$B$35 -> 0.29539376 | R6: ='01_Inputs'!$B$33 -> 99.4 | S6: ='05_Outputs'!B20 -> 8.4988566
A7: ='01_Inputs'!$B$5 -> Base | B7: ='04_Waterfall'!A7 -> 2029 | C7: ='04_Waterfall'!B7 -> 59.5 | D7: ='04_Waterfall'!C7 -> 2.975 | E7: ='04_Waterfall'!D7 -> 0 | F7: ='04_Waterfall'!E7 -> 56.525 | G7: ='04_Waterfall'!F7 -> 0.059 | H7: ='04_Waterfall'!G7 -> -26.61372 | I7: ='04_Waterfall'!H7 -> 0 | ... P7: ='04_Waterfall'!O7 -> 0.6 | Q7: ='01_Inputs'!$B$35 -> 0.29539376 | R7: ='01_Inputs'!$B$33 -> 99.4 | S7: ='05_Outputs'!B21 -> 8.8356054
A8: ='01_Inputs'!$B$5 -> Base | B8: ='04_Waterfall'!A8 -> 2030 | C8: ='04_Waterfall'!B8 -> 60.3 | D8: ='04_Waterfall'!C8 -> 3.015 | E8: ='04_Waterfall'!D8 -> 0 | F8: ='04_Waterfall'!E8 -> 57.285 | G8: ='04_Waterfall'!F8 -> 0.06 | H8: ='04_Waterfall'!G8 -> -28.2744 | I8: ='04_Waterfall'!H8 -> 0 | ... P8: ='04_Waterfall'!O8 -> 0.61054104 | Q8: ='01_Inputs'!$B$35 -> 0.29539376 | R8: ='01_Inputs'!$B$33 -> 99.4 | S8: ='05_Outputs'!B22 -> 8.5695502
A9: ='01_Inputs'!$B$5 -> Base | B9: ='04_Waterfall'!A9 -> 2031 | C9: ='04_Waterfall'!B9 -> 61.2 | D9: ='04_Waterfall'!C9 -> 3.06 | E9: ='04_Waterfall'!D9 -> 0 | F9: ='04_Waterfall'!E9 -> 58.14 | G9: ='04_Waterfall'!F9 -> 0.06 | H9: ='04_Waterfall'!G9 -> -28.2744 | I9: ='04_Waterfall'!H9 -> 0 | ... P9: ='04_Waterfall'!O9 -> 0.62096774 | Q9: ='01_Inputs'!$B$35 -> 0.29539376 | R9: ='01_Inputs'!$B$33 -> 99.4 | S9: ='05_Outputs'!B23 -> 8.8221119
A10: ='01_Inputs'!$B$5 -> Base | B10: ='04_Waterfall'!A10 -> 2032 | C10: ='04_Waterfall'!B10 -> 62.2 | D10: ='04_Waterfall'!C10 -> 3.11 | E10: ='04_Waterfall'!D10 -> 0 | F10: ='04_Waterfall'!E10 -> 59.09 | G10: ='04_Waterfall'!F10 -> 0.061 | H10: ='04_Waterfall'!G10 -> -28.74564 | I10: ='04_Waterfall'!H10 -> 0 | ... P10: ='04_Waterfall'!O10 -> 0.63135048 | Q10: ='01_Inputs'!$B$35 -> 0.29539376 | R10: ='01_Inputs'!$B$33 -> 99.4 | S10: ='05_Outputs'!B24 -> 8.9635346
A11: ='01_Inputs'!$B$5 -> Base | B11: ='04_Waterfall'!A11 -> 2033 | C11: ='04_Waterfall'!B11 -> 63.3 | D11: ='04_Waterfall'!C11 -> 3.165 | E11: ='04_Waterfall'!D11 -> 0 | F11: ='04_Waterfall'!E11 -> 60.135 | G11: ='04_Waterfall'!F11 -> 0.061 | H11: ='04_Waterfall'!G11 -> -28.74564 | I11: ='04_Waterfall'!H11 -> 0 | ... P11: ='04_Waterfall'!O11 -> 0.62037915 | Q11: ='01_Inputs'!$B$35 -> 0.29539376 | R11: ='01_Inputs'!$B$33 -> 99.4 | S11: ='05_Outputs'!B25 -> 9.2722211
A12: ='01_Inputs'!$B$5 -> Base | B12: ='04_Waterfall'!A12 -> 2034 | C12: ='04_Waterfall'!B12 -> 64.3 | D12: ='04_Waterfall'!C12 -> 3.215 | E12: ='04_Waterfall'!D12 -> 0 | F12: ='04_Waterfall'!E12 -> 61.085 | G12: ='04_Waterfall'!F12 -> 0.062 | H12: ='04_Waterfall'!G12 -> -29.21688 | I12: ='04_Waterfall'!H12 -> 0 | ... P12: ='04_Waterfall'!O12 -> 0.61073095 | Q12: ='01_Inputs'!$B$35 -> 0.29539376 | R12: ='01_Inputs'!$B$33 -> 99.4 | S12: ='05_Outputs'!B26 -> 9.4136438
A13: ='01_Inputs'!$B$5 -> Base | B13: ='04_Waterfall'!A13 -> 2035 | C13: ='04_Waterfall'!B13 -> 65.1 | D13: ='04_Waterfall'!C13 -> 3.255 | E13: ='04_Waterfall'!D13 -> 0 | F13: ='04_Waterfall'!E13 -> 61.845 | G13: ='04_Waterfall'!F13 -> 0.062 | H13: ='04_Waterfall'!G13 -> -29.21688 | I13: ='04_Waterfall'!H13 -> 0 | ... P13: ='04_Waterfall'!O13 -> 0.60322581 | Q13: ='01_Inputs'!$B$35 -> 0.29539376 | R13: ='01_Inputs'!$B$33 -> 99.4 | S13: ='05_Outputs'!B27 -> 9.638143
... A17: ='01_Inputs'!$B$5 -> Base | B17: ='04_Waterfall'!A17 -> 2039 | C17: ='04_Waterfall'!B17 -> 67.5 | D17: ='04_Waterfall'!C17 -> 3.375 | E17: ='04_Waterfall'!D17 -> 0 | F17: ='04_Waterfall'!E17 -> 64.125 | G17: ='04_Waterfall'!F17 -> 0.062 | H17: ='04_Waterfall'!G17 -> -29.21688 | I17: ='04_Waterfall'!H17 -> 0 | ... P17: ='04_Waterfall'!O17 -> 0.58177778 | Q17: ='01_Inputs'!$B$35 -> 0.29539376 | R17: ='01_Inputs'!$B$33 -> 99.4 | S17: ='05_Outputs'!B31 -> 100.06759
A19: How to use | B19: Python data feed: read table A1:S17. For CSV: File → Save As → CSV (UTF-8). In Python: pandas.read_excel(..., sheet_name='07_Export') or read_csv on exported file.
